<mujoco model="humanoid">
  <compiler angle="degree" inertiafromgeom="true" coordinate="global"/>
  <default>
    <joint damping="1" limited="true"/>
    <geom conaffinity="7" condim="1" contype="7" margin="0.001" material="geom" rgba="0.8 0.6 .4 1"/>
    <motor ctrllimited="true" ctrlrange="-1. 1."/>
  </default>
  <option timestep="0.005"/>
  <asset>
    <texture type="skybox" file="./common/sky1.png" gridsize="3 4" gridlayout=".U..LFRB.D.." width="8192" height="8192"/>
    <texture builtin="flat" height="1278" mark="cross" markrgb="1 1 1" name="texgeom" random="0.01" rgb1=".8 .6 .4" rgb2=".8 .6 .4" type="cube" width="127"/>
    <texture builtin="checker" height="100" name="texplane" rgb1="0 0 0" rgb2=".8 .8 .8" type="2d" width="100"/>
    <material name="MatPlane" reflectance="0.5" shininess="1" specular="1" texrepeat="60 60" texture="texplane"/>
    <material name="geom" emission="0.2" texture="texgeom" texuniform="true"/>
  </asset>
  <worldbody>
    <light cutoff="100" diffuse="1 1 1" dir="-0 0 -1.3" directional="true" exponent="1" pos="0 0 1.3" specular=".1 .1 .1"/>
    <geom condim="3" friction="1. .1 .1" material="MatPlane" name="floor" pos="0 0 0" rgba=".8 .9 .8 1" size="20 20 0.125" type="plane"/>
    <body name="root" user="0.0000 -0.0000 0.0000" pos="0.0000 -0.0000 0.0000">
      <geom density="1000" fromto="-0.0825 0.0000 0.0160 0.0825 0.0000 0.0160" size="0.0740" type="capsule"/>
      <joint armature="0.0" damping="0.0" limited="false" name="root" pos="0.0000 -0.0000 0.0000" stiffness="0" type="free"/>
      <body name="lhip" pos="-0.0481 0.0000 0.0000" user="-0.0961 0.0000 0.0000">
        <body name="lfem" pos="-0.0961 0.0000 -0.2072" user="-0.0961 0.0000 -0.4145">
          <joint name="lfem_y" axis="0.00 1.00 0.00" pos="-0.0961 0.0000 0.0000" range="-180.00 180.00" type="hinge" armature="0.01" stiffness="1.0" damping="5.0"/>
          <joint name="lfem_z" axis="0.00 0.00 1.00" pos="-0.0961 0.0000 0.0000" range="-180.00 180.00" type="hinge" armature="0.01" stiffness="1.0" damping="5.0"/>
          <joint name="lfem_x" axis="1.00 0.00 0.00" pos="-0.0961 0.0000 0.0000" range="-180.00 180.00" type="hinge" armature="0.01" stiffness="1.0" damping="5.0"/>
          <geom fromto="-0.0961 0.0000 0.0000 -0.0961 0.0000 -0.4145" size="0.0440" type="capsule"/>
          <body name="lkn" pos="-0.0961 0.0000 -0.6066" user="-0.0961 0.0000 -0.7987">
            <joint name="lkn_y" axis="0.00 1.00 0.00" pos="-0.0961 0.0000 -0.4145" range="-180.00 180.00" type="hinge" armature="0.01" stiffness="1.0" damping="5.0"/>
            <joint name="lkn_z" axis="0.00 0.00 1.00" pos="-0.0961 0.0000 -0.4145" range="-180.00 180.00" type="hinge" armature="0.01" stiffness="1.0" damping="5.0"/>
            <joint name="lkn_x" axis="1.00 0.00 0.00" pos="-0.0961 0.0000 -0.4145" range="-180.00 180.00" type="hinge" armature="0.01" stiffness="1.0" damping="5.0"/>
            <geom fromto="-0.0961 0.0000 -0.4395 -0.0961 0.0000 -0.7737" size="0.0340" type="capsule"/>
            <body name="lft" pos="-0.0961 -0.0250 -0.7987" user="-0.0961 -0.0500 -0.7987">
              <geom fromto="-0.1201 0.0475 -0.7987 -0.1201 -0.1175 -0.7987" size="0.0240" type="capsule"/>
              <joint name="lft_y" axis="0.00 1.00 0.00" pos="-0.0961 0.0000 -0.7987" range="-180.00 180.00" type="hinge" armature="0.01" stiffness="1.0" damping="5.0"/>
              <joint name="lft_z" axis="0.00 0.00 1.00" pos="-0.0961 0.0000 -0.7987" range="-180.00 180.00" type="hinge" armature="0.01" stiffness="1.0" damping="5.0"/>
              <joint name="lft_x" axis="1.00 0.00 0.00" pos="-0.0961 0.0000 -0.7987" range="-180.00 180.00" type="hinge" armature="0.01" stiffness="1.0" damping="5.0"/>
              <geom fromto="-0.0661 0.0475 -0.7987 -0.0661 -0.1175 -0.7987" size="0.0240" type="capsule"/>
            </body>
          </body>
        </body>
      </body>
      <body name="rhip" pos="0.0481 0.0000 0.0000" user="0.0961 0.0000 0.0000">
        <body name="rfem" pos="0.0961 0.0000 -0.2072" user="0.0961 0.0000 -0.4145">
          <joint name="rfem_y" axis="0.00 1.00 0.00" pos="0.0961 0.0000 0.0000" range="-180.00 180.00" type="hinge" armature="0.01" stiffness="1.0" damping="5.0"/>
          <joint name="rfem_z" axis="0.00 0.00 1.00" pos="0.0961 0.0000 0.0000" range="-180.00 180.00" type="hinge" armature="0.01" stiffness="1.0" damping="5.0"/>
          <joint name="rfem_x" axis="1.00 0.00 0.00" pos="0.0961 0.0000 0.0000" range="-180.00 180.00" type="hinge" armature="0.01" stiffness="1.0" damping="5.0"/>
          <geom fromto="0.0961 0.0000 0.0000 0.0961 0.0000 -0.4145" size="0.0440" type="capsule"/>
          <body name="rkn" pos="0.0961 0.0000 -0.6066" user="0.0961 0.0000 -0.7987">
            <joint name="rkn_y" axis="0.00 1.00 0.00" pos="0.0961 0.0000 -0.4145" range="-180.00 180.00" type="hinge" armature="0.01" stiffness="1.0" damping="5.0"/>
            <joint name="rkn_z" axis="0.00 0.00 1.00" pos="0.0961 0.0000 -0.4145" range="-180.00 180.00" type="hinge" armature="0.01" stiffness="1.0" damping="5.0"/>
            <joint name="rkn_x" axis="1.00 0.00 0.00" pos="0.0961 0.0000 -0.4145" range="-180.00 180.00" type="hinge" armature="0.01" stiffness="1.0" damping="5.0"/>
            <geom fromto="0.0961 0.0000 -0.4395 0.0961 0.0000 -0.7737" size="0.0340" type="capsule"/>
            <body name="rft" pos="0.0961 -0.0250 -0.7987" user="0.0961 -0.0500 -0.7987">
              <geom fromto="0.1201 0.0475 -0.7987 0.1201 -0.1175 -0.7987" size="0.0240" type="capsule"/>
              <joint name="rft_y" axis="0.00 1.00 0.00" pos="0.0961 0.0000 -0.7987" range="-180.00 180.00" type="hinge" armature="0.01" stiffness="1.0" damping="5.0"/>
              <joint name="rft_z" axis="0.00 0.00 1.00" pos="0.0961 0.0000 -0.7987" range="-180.00 180.00" type="hinge" armature="0.01" stiffness="1.0" damping="5.0"/>
              <joint name="rft_x" axis="1.00 0.00 0.00" pos="0.0961 0.0000 -0.7987" range="-180.00 180.00" type="hinge" armature="0.01" stiffness="1.0" damping="5.0"/>
              <geom fromto="0.0661 0.0475 -0.7987 0.0661 -0.1175 -0.7987" size="0.0240" type="capsule"/>
            </body>
          </body>
        </body>
      </body>
      <body name="back" pos="0.0000 0.0000 0.2892" user="0.0000 0.0000 0.5783">
        <geom fromto="0.0866 0.0000 0.3072 -0.0866 0.0000 0.3072" size="0.0700" type="capsule"/>
        <geom fromto="0.0866 0.0000 0.4492 -0.0866 0.0000 0.4492" size="0.0690" type="capsule"/>
        <joint name="back_y" axis="0.00 1.00 0.00" pos="0.0000 -0.0000 0.0000" range="-180.00 180.00" type="hinge" armature="0.01" stiffness="1.0" damping="5.0"/>
        <joint name="back_z" axis="0.00 0.00 1.00" pos="0.0000 -0.0000 0.0000" range="-180.00 180.00" type="hinge" armature="0.01" stiffness="1.0" damping="5.0"/>
        <joint name="back_x" axis="1.00 0.00 0.00" pos="0.0000 -0.0000 0.0000" range="-180.00 180.00" type="hinge" armature="0.01" stiffness="1.0" damping="5.0"/>
        <geom fromto="0.0866 0.0000 0.1631 -0.0866 0.0000 0.1631" size="0.0700" type="capsule"/>
        <body name="neck" pos="0.0000 0.0000 0.7081" user="0.0000 0.0000 0.8378">
          <joint name="neck_y" axis="0.00 1.00 0.00" pos="0.0000 0.0000 0.5783" range="-180.00 180.00" type="hinge" armature="0.01" stiffness="1.0" damping="5.0"/>
          <joint name="neck_z" axis="0.00 0.00 1.00" pos="0.0000 0.0000 0.5783" range="-180.00 180.00" type="hinge" armature="0.01" stiffness="1.0" damping="5.0"/>
          <joint name="neck_x" axis="1.00 0.00 0.00" pos="0.0000 0.0000 0.5783" range="-180.00 180.00" type="hinge" armature="0.01" stiffness="1.0" damping="5.0"/>
          <geom fromto="0.0000 0.0000 0.6323 0.0000 0.0000 0.6918" size="0.0360" type="capsule"/>
          <body name="head" pos="0.0000 0.0000 0.8628" user="0.0000 0.0000 0.8878">
            <joint name="head_y" axis="0.00 1.00 0.00" pos="0.0000 0.0000 0.8378" range="-180.00 180.00" type="hinge" armature="0.01" stiffness="1.0" damping="5.0"/>
            <joint name="head_z" axis="0.00 0.00 1.00" pos="0.0000 0.0000 0.8378" range="-180.00 180.00" type="hinge" armature="0.01" stiffness="1.0" damping="5.0"/>
            <joint name="head_x" axis="1.00 0.00 0.00" pos="0.0000 0.0000 0.8378" range="-180.00 180.00" type="hinge" armature="0.01" stiffness="1.0" damping="5.0"/>
            <geom fromto="0.0000 0.0000 0.7558 0.0000 0.0000 0.8058" size="0.0600" type="capsule"/>
          </body>
        </body>
        <body name="lcla" pos="-0.1024 0.0000 0.5783" user="-0.2048 0.0000 0.5783">
          <joint name="lcla_y" axis="0.00 1.00 0.00" pos="0.0000 0.0000 0.5783" range="-180.00 180.00" type="hinge" armature="0.01" stiffness="1.0" damping="5.0"/>
          <joint name="lcla_z" axis="0.00 0.00 1.00" pos="0.0000 0.0000 0.5783" range="-180.00 180.00" type="hinge" armature="0.01" stiffness="1.0" damping="5.0"/>
          <joint name="lcla_x" axis="1.00 0.00 0.00" pos="0.0000 0.0000 0.5783" range="-180.00 180.00" type="hinge" armature="0.01" stiffness="1.0" damping="5.0"/>
          <geom fromto="0.0000 0.0000 0.5783 -0.2048 0.0000 0.5783" size="0.0520" type="capsule"/>
          <body name="lshd" pos="-0.3420 0.0000 0.5783" user="-0.4791 0.0000 0.5783">
            <joint name="lshd_y" axis="0.00 1.00 0.00" pos="-0.2048 0.0000 0.5783" range="-180.00 180.00" type="hinge" armature="0.01" stiffness="1.0" damping="5.0"/>
            <joint name="lshd_z" axis="0.00 0.00 1.00" pos="-0.2048 0.0000 0.5783" range="-180.00 180.00" type="hinge" armature="0.01" stiffness="1.0" damping="5.0"/>
            <joint name="lshd_x" axis="1.00 0.00 0.00" pos="-0.2048 0.0000 0.5783" range="-180.00 180.00" type="hinge" armature="0.01" stiffness="1.0" damping="5.0"/>
            <geom fromto="-0.2048 0.0000 0.5783 -0.4791 0.0000 0.5783" size="0.0410" type="capsule"/>
            <body name="lelb" pos="-0.6000 0.0000 0.5783" user="-0.7210 0.0000 0.5783">
              <joint name="lelb_y" axis="0.00 1.00 0.00" pos="-0.4791 0.0000 0.5783" range="-180.00 180.00" type="hinge" armature="0.01" stiffness="1.0" damping="5.0"/>
              <joint name="lelb_z" axis="0.00 0.00 1.00" pos="-0.4791 0.0000 0.5783" range="-180.00 180.00" type="hinge" armature="0.01" stiffness="1.0" damping="5.0"/>
              <joint name="lelb_x" axis="1.00 0.00 0.00" pos="-0.4791 0.0000 0.5783" range="-180.00 180.00" type="hinge" armature="0.01" stiffness="1.0" damping="5.0"/>
              <geom fromto="-0.4791 0.0000 0.5783 -0.7210 0.0000 0.5783" size="0.0370" type="capsule"/>
              <body name="lhnd" pos="-0.7460 0.0000 0.5783" user="-0.7710 0.0000 0.5783">
                <joint name="lhnd_y" axis="0.00 1.00 0.00" pos="-0.7210 0.0000 0.5783" range="-180.00 180.00" type="hinge" armature="0.01" stiffness="1.0" damping="5.0"/>
                <joint name="lhnd_z" axis="0.00 0.00 1.00" pos="-0.7210 0.0000 0.5783" range="-180.00 180.00" type="hinge" armature="0.01" stiffness="1.0" damping="5.0"/>
                <joint name="lhnd_x" axis="1.00 0.00 0.00" pos="-0.7210 0.0000 0.5783" range="-180.00 180.00" type="hinge" armature="0.01" stiffness="1.0" damping="5.0"/>
                <geom fromto="-0.7210 0.0000 0.5783 -0.7710 0.0000 0.5783" size="0.0300" type="capsule"/>
              </body>
            </body>
          </body>
        </body>
        <body name="rcla" pos="0.1024 0.0000 0.5783" user="0.2048 0.0000 0.5783">
          <joint name="rcla_y" axis="0.00 1.00 0.00" pos="-0.0000 0.0000 0.5783" range="-180.00 180.00" type="hinge" armature="0.01" stiffness="1.0" damping="5.0"/>
          <joint name="rcla_z" axis="0.00 0.00 1.00" pos="-0.0000 0.0000 0.5783" range="-180.00 180.00" type="hinge" armature="0.01" stiffness="1.0" damping="5.0"/>
          <joint name="rcla_x" axis="1.00 0.00 0.00" pos="-0.0000 0.0000 0.5783" range="-180.00 180.00" type="hinge" armature="0.01" stiffness="1.0" damping="5.0"/>
          <geom fromto="-0.0000 0.0000 0.5783 0.2048 0.0000 0.5783" size="0.0520" type="capsule"/>
          <body name="rshd" pos="0.3420 0.0000 0.5783" user="0.4791 0.0000 0.5783">
            <joint name="rshd_y" axis="0.00 1.00 0.00" pos="0.2048 0.0000 0.5783" range="-180.00 180.00" type="hinge" armature="0.01" stiffness="1.0" damping="5.0"/>
            <joint name="rshd_z" axis="0.00 0.00 1.00" pos="0.2048 0.0000 0.5783" range="-180.00 180.00" type="hinge" armature="0.01" stiffness="1.0" damping="5.0"/>
            <joint name="rshd_x" axis="1.00 0.00 0.00" pos="0.2048 0.0000 0.5783" range="-180.00 180.00" type="hinge" armature="0.01" stiffness="1.0" damping="5.0"/>
            <geom fromto="0.2048 0.0000 0.5783 0.4791 0.0000 0.5783" size="0.0410" type="capsule"/>
            <body name="relb" pos="0.6000 0.0000 0.5783" user="0.7210 0.0000 0.5783">
              <joint name="relb_y" axis="0.00 1.00 0.00" pos="0.4791 0.0000 0.5783" range="-180.00 180.00" type="hinge" armature="0.01" stiffness="1.0" damping="5.0"/>
              <joint name="relb_z" axis="0.00 0.00 1.00" pos="0.4791 0.0000 0.5783" range="-180.00 180.00" type="hinge" armature="0.01" stiffness="1.0" damping="5.0"/>
              <joint name="relb_x" axis="1.00 0.00 0.00" pos="0.4791 0.0000 0.5783" range="-180.00 180.00" type="hinge" armature="0.01" stiffness="1.0" damping="5.0"/>
              <geom fromto="0.4791 0.0000 0.5783 0.7210 0.0000 0.5783" size="0.0370" type="capsule"/>
              <body name="rhnd" pos="0.7460 0.0000 0.5783" user="0.7710 0.0000 0.5783">
                <joint name="rhnd_y" axis="0.00 1.00 0.00" pos="0.7210 0.0000 0.5783" range="-180.00 180.00" type="hinge" armature="0.01" stiffness="1.0" damping="5.0"/>
                <joint name="rhnd_z" axis="0.00 0.00 1.00" pos="0.7210 0.0000 0.5783" range="-180.00 180.00" type="hinge" armature="0.01" stiffness="1.0" damping="5.0"/>
                <joint name="rhnd_x" axis="1.00 0.00 0.00" pos="0.7210 0.0000 0.5783" range="-180.00 180.00" type="hinge" armature="0.01" stiffness="1.0" damping="5.0"/>
                <geom fromto="0.7210 0.0000 0.5783 0.7710 0.0000 0.5783" size="0.0300" type="capsule"/>
              </body>
            </body>
          </body>
        </body>
      </body>
    </body>
  </worldbody>
  <actuator>
  </actuator>
</mujoco>
