<mujoco model="humanoid">
  <compiler angle="degree" inertiafromgeom="true"/>
  <default>
    <joint damping="1" limited="true"/>
    <geom conaffinity="1" condim="1" contype="1" margin="0.001" material="geom" rgba="0.8 0.6 .4 1"/>
    <motor ctrllimited="true" ctrlrange="-.4 .4"/>
  </default>
  <option integrator="RK4" iterations="50" solver="PGS" timestep="0.003"/>
  <asset>
    <texture builtin="gradient" height="100" rgb1=".4 .5 .6" rgb2="0 0 0" type="skybox" width="100"/>
    <texture builtin="flat" height="1278" mark="cross" markrgb="1 1 1" name="texgeom" random="0.01" rgb1=".8 .6 .4" rgb2=".8 .6 .4" type="cube" width="127"/>
    <texture builtin="checker" height="100" name="texplane" rgb1="0 0 0" rgb2=".8 .8 .8" type="2d" width="100"/>
    <material name="MatPlane" reflectance="0.5" shininess="1" specular="1" texrepeat="60 60" texture="texplane"/>
    <material name="geom" texture="texgeom" texuniform="true"/>
  </asset>
  <worldbody>
    <light cutoff="100" diffuse="1 1 1" dir="-0 0 -1.3" directional="true" exponent="1" pos="0 0 1.3" specular=".1 .1 .1"/>
    <geom condim="3" friction="1 .1 .1" material="MatPlane" name="floor" pos="0 0 0" rgba=".8 .9 .8 1" size="20 20 0.125" type="plane"/>
    <body name="root" user="0.0000 -0.0000 0.0000">
      <joint armature="0" damping="0" limited="false" name="root" pos="0.0000 -0.0000 0.0000" stiffness="0" type="free"/>
      <geom pos="0.0000 -0.0000 0.0000" size="0.0300 0.0300 0.0300" type="ellipsoid" quat="1.0000 -0.0000 -0.0000 -0.0000"/>
      <body name="lhipjoint" user="0.0963 -0.0494 -0.0918">
        <geom fromto="0.0136 -0.0070 -0.0129 0.0827 -0.0425 -0.0789" size="0.0300" type="capsule"/>
        <body name="lfemur" user="0.2274 -0.0494 -0.4521">
          <joint armature="0.01" axis="0.0000 -1.0000 0.0000" damping="5" limited="true" name="lfemur_z" pos="0.0963 -0.0494 -0.0918" range="-60.0000 70.0000" stiffness="10" type="hinge"/>
          <joint armature="0.01" axis="-0.3420 -0.0000 0.9397" damping="5" limited="true" name="lfemur_y" pos="0.0963 -0.0494 -0.0918" range="-70.0000 70.0000" stiffness="10" type="hinge"/>
          <joint armature="0.01" axis="0.9397 0.0000 0.3420" damping="5" limited="true" name="lfemur_x" pos="0.0963 -0.0494 -0.0918" range="-160.0000 20.0000" stiffness="10" type="hinge"/>
          <geom fromto="0.1031 -0.0494 -0.1106 0.2206 -0.0494 -0.4333" size="0.0300" type="capsule"/>
          <body name="ltibia" user="0.3657 -0.0494 -0.8321">
            <joint armature="0.01" axis="0.9397 0.0000 0.3420" damping="5" limited="true" name="ltibia_x" pos="0.2274 -0.0494 -0.4521" range="-10.0000 170.0000" stiffness="10" type="hinge"/>
            <geom fromto="0.2343 -0.0494 -0.4709 0.3589 -0.0494 -0.8133" size="0.0300" type="capsule"/>
            <body name="lfoot" user="0.3731 -0.1606 -0.8523">
              <joint armature="0.01" axis="-0.3420 -0.0000 0.9397" damping="5" limited="true" name="lfoot_z" pos="0.3657 -0.0494 -0.8321" range="-70.0000 20.0000" stiffness="10" type="hinge"/>
              <joint armature="0.01" axis="0.9397 0.0000 0.3420" damping="5" limited="true" name="lfoot_x" pos="0.3657 -0.0494 -0.8321" range="-45.0000 90.0000" stiffness="10" type="hinge"/>
              <geom fromto="0.3670 -0.0691 -0.8356 0.3718 -0.1410 -0.8487" size="0.0300" type="capsule"/>
              <body name="ltoes" user="0.3731 -0.2178 -0.8523">
                <joint armature="0.01" axis="0.9397 0.0000 0.3420" damping="5" limited="true" name="ltoes_x" pos="0.3731 -0.1606 -0.8523" range="-90.0000 20.0000" stiffness="10" type="hinge"/>
                <geom fromto="0.3731 -0.1806 -0.8523 0.3731 -0.1978 -0.8523" size="0.0300" type="capsule"/>
              </body>
            </body>
          </body>
        </body>
      </body>
      <body name="rhipjoint" user="-0.0963 -0.0494 -0.0918">
        <geom fromto="-0.0136 -0.0070 -0.0129 -0.0827 -0.0425 -0.0789" size="0.0300" type="capsule"/>
        <body name="rfemur" user="-0.2274 -0.0494 -0.4521">
          <joint armature="0.01" axis="0.0000 -1.0000 -0.0000" damping="5" limited="true" name="rfemur_z" pos="-0.0963 -0.0494 -0.0918" range="-70.0000 60.0000" stiffness="10" type="hinge"/>
          <joint armature="0.01" axis="0.3420 -0.0000 0.9397" damping="5" limited="true" name="rfemur_y" pos="-0.0963 -0.0494 -0.0918" range="-70.0000 70.0000" stiffness="10" type="hinge"/>
          <joint armature="0.01" axis="0.9397 0.0000 -0.3420" damping="5" limited="true" name="rfemur_x" pos="-0.0963 -0.0494 -0.0918" range="-160.0000 20.0000" stiffness="10" type="hinge"/>
          <geom fromto="-0.1031 -0.0494 -0.1106 -0.2206 -0.0494 -0.4333" size="0.0300" type="capsule"/>
          <body name="rtibia" user="-0.3657 -0.0494 -0.8321">
            <joint armature="0.01" axis="0.9397 0.0000 -0.3420" damping="5" limited="true" name="rtibia_x" pos="-0.2274 -0.0494 -0.4521" range="-10.0000 170.0000" stiffness="10" type="hinge"/>
            <geom fromto="-0.2343 -0.0494 -0.4709 -0.3589 -0.0494 -0.8133" size="0.0300" type="capsule"/>
            <body name="rfoot" user="-0.3731 -0.1606 -0.8523">
              <joint armature="0.01" axis="0.3420 -0.0000 0.9397" damping="5" limited="true" name="rfoot_z" pos="-0.3657 -0.0494 -0.8321" range="-20.0000 70.0000" stiffness="10" type="hinge"/>
              <joint armature="0.01" axis="0.9397 -0.0000 -0.3420" damping="5" limited="true" name="rfoot_x" pos="-0.3657 -0.0494 -0.8321" range="-45.0000 90.0000" stiffness="10" type="hinge"/>
              <geom fromto="-0.3670 -0.0691 -0.8356 -0.3718 -0.1410 -0.8487" size="0.0300" type="capsule"/>
              <body name="rtoes" user="-0.3731 -0.2178 -0.8523">
                <joint armature="0.01" axis="0.9397 -0.0000 -0.3420" damping="5" limited="true" name="rtoes_x" pos="-0.3731 -0.1606 -0.8523" range="-90.0000 20.0000" stiffness="10" type="hinge"/>
                <geom fromto="-0.3731 -0.1806 -0.8523 -0.3731 -0.1978 -0.8523" size="0.0300" type="capsule"/>
              </body>
            </body>
          </body>
        </body>
      </body>
      <body name="lowerback" user="0.0006 0.0081 0.1132">
        <joint armature="0.01" axis="0.0000 -1.0000 0.0000" damping="5" limited="true" name="lowerback_z" pos="0.0000 -0.0000 0.0000" range="-30.0000 30.0000" stiffness="10" type="hinge"/>
        <joint armature="0.01" axis="0.0000 -0.0000 1.0000" damping="5" limited="true" name="lowerback_y" pos="0.0000 -0.0000 0.0000" range="-30.0000 30.0000" stiffness="10" type="hinge"/>
        <joint armature="0.01" axis="1.0000 0.0000 0.0000" damping="5" limited="true" name="lowerback_x" pos="0.0000 -0.0000 0.0000" range="-20.0000 45.0000" stiffness="10" type="hinge"/>
        <geom fromto="0.0001 0.0014 0.0199 0.0005 0.0066 0.0933" size="0.0300" type="capsule"/>
        <body name="upperback" user="0.0011 0.0071 0.2268">
          <joint armature="0.01" axis="0.0000 -1.0000 0.0000" damping="5" limited="true" name="upperback_z" pos="0.0006 0.0081 0.1132" range="-30.0000 30.0000" stiffness="10" type="hinge"/>
          <joint armature="0.01" axis="0.0000 -0.0000 1.0000" damping="5" limited="true" name="upperback_y" pos="0.0006 0.0081 0.1132" range="-30.0000 30.0000" stiffness="10" type="hinge"/>
          <joint armature="0.01" axis="1.0000 0.0000 0.0000" damping="5" limited="true" name="upperback_x" pos="0.0006 0.0081 0.1132" range="-20.0000 45.0000" stiffness="10" type="hinge"/>
          <geom fromto="0.0007 0.0079 0.1332 0.0010 0.0073 0.2068" size="0.0300" type="capsule"/>
          <body name="thorax" user="0.0010 0.0024 0.3407">
            <joint armature="0.01" axis="0.0000 -1.0000 0.0000" damping="5" limited="true" name="thorax_z" pos="0.0011 0.0071 0.2268" range="-30.0000 30.0000" stiffness="10" type="hinge"/>
            <joint armature="0.01" axis="0.0000 -0.0000 1.0000" damping="5" limited="true" name="thorax_y" pos="0.0011 0.0071 0.2268" range="-30.0000 30.0000" stiffness="10" type="hinge"/>
            <joint armature="0.01" axis="1.0000 0.0000 0.0000" damping="5" limited="true" name="thorax_x" pos="0.0011 0.0071 0.2268" range="-20.0000 45.0000" stiffness="10" type="hinge"/>
            <geom fromto="0.0011 0.0063 0.2468 0.0010 0.0033 0.3207" size="0.0300" type="capsule"/>
            <body name="lowerneck" user="-0.0023 -0.0083 0.4312">
              <joint armature="0.01" axis="0.0000 -1.0000 0.0000" damping="5" limited="true" name="lowerneck_z" pos="0.0010 0.0024 0.3407" range="-30.0000 30.0000" stiffness="10" type="hinge"/>
              <joint armature="0.01" axis="0.0000 -0.0000 1.0000" damping="5" limited="true" name="lowerneck_y" pos="0.0010 0.0024 0.3407" range="-30.0000 30.0000" stiffness="10" type="hinge"/>
              <joint armature="0.01" axis="1.0000 0.0000 0.0000" damping="5" limited="true" name="lowerneck_x" pos="0.0010 0.0024 0.3407" range="-20.0000 45.0000" stiffness="10" type="hinge"/>
              <geom fromto="0.0003 0.0001 0.3606 -0.0015 -0.0059 0.4114" size="0.0300" type="capsule"/>
              <body name="upperneck" user="-0.0013 -0.0038 0.5212">
                <joint armature="0.01" axis="0.0000 -1.0000 0.0000" damping="5" limited="true" name="upperneck_z" pos="-0.0023 -0.0083 0.4312" range="-30.0000 30.0000" stiffness="10" type="hinge"/>
                <joint armature="0.01" axis="0.0000 -0.0000 1.0000" damping="5" limited="true" name="upperneck_y" pos="-0.0023 -0.0083 0.4312" range="-30.0000 30.0000" stiffness="10" type="hinge"/>
                <joint armature="0.01" axis="1.0000 0.0000 0.0000" damping="5" limited="true" name="upperneck_x" pos="-0.0023 -0.0083 0.4312" range="-20.0000 45.0000" stiffness="10" type="hinge"/>
                <geom fromto="-0.0020 -0.0073 0.4512 -0.0015 -0.0048 0.5012" size="0.0300" type="capsule"/>
                <body name="head" user="-0.0006 -0.0008 0.6176">
                  <joint armature="0.01" axis="0.0000 -1.0000 0.0000" damping="5" limited="true" name="head_z" pos="-0.0013 -0.0038 0.5212" range="-30.0000 30.0000" stiffness="10" type="hinge"/>
                  <joint armature="0.01" axis="0.0000 -0.0000 1.0000" damping="5" limited="true" name="head_y" pos="-0.0013 -0.0038 0.5212" range="-30.0000 30.0000" stiffness="10" type="hinge"/>
                  <joint armature="0.01" axis="1.0000 0.0000 0.0000" damping="5" limited="true" name="head_x" pos="-0.0013 -0.0038 0.5212" range="-20.0000 45.0000" stiffness="10" type="hinge"/>
                  <geom fromto="-0.0011 -0.0031 0.5412 -0.0007 -0.0014 0.5976" size="0.0300" type="capsule"/>
                </body>
              </body>
            </body>
            <body name="lclavicle" user="0.1790 -0.0149 0.4121">
              <joint armature="0.01" axis="0.0000 -1.0000 0.0000" damping="5" limited="true" name="lclavicle_z" pos="0.0010 0.0024 0.3407" range="0.0000 20.0000" stiffness="10" type="hinge"/>
              <joint armature="0.01" axis="0.0000 -0.0000 1.0000" damping="5" limited="true" name="lclavicle_y" pos="0.0010 0.0024 0.3407" range="-20.0000 10.0000" stiffness="10" type="hinge"/>
              <geom fromto="0.0334 -0.0007 0.3537 0.1466 -0.0118 0.3991" size="0.0300" type="capsule"/>
              <body name="lhumerus" user="0.4599 -0.0149 0.4121">
                <joint armature="0.01" axis="-0.0000 0.8660 -0.5000" damping="5" limited="true" name="lhumerus_z" pos="0.1790 -0.0149 0.4121" range="-90.0000 90.0000" stiffness="10" type="hinge"/>
                <joint armature="0.01" axis="-1.0000 -0.0000 -0.0000" damping="5" limited="true" name="lhumerus_y" pos="0.1790 -0.0149 0.4121" range="-90.0000 90.0000" stiffness="10" type="hinge"/>
                <joint armature="0.01" axis="0.0000 -0.5000 -0.8660" damping="5" limited="true" name="lhumerus_x" pos="0.1790 -0.0149 0.4121" range="-60.0000 90.0000" stiffness="10" type="hinge"/>
                <geom fromto="0.2065 -0.0149 0.4121 0.4324 -0.0149 0.4121" size="0.0300" type="capsule"/>
                <body name="lradius" user="0.6374 -0.0149 0.4121">
                  <joint armature="0.01" axis="0.0000 -0.5000 -0.8660" damping="5" limited="true" name="lradius_x" pos="0.4599 -0.0149 0.4121" range="-10.0000 170.0000" stiffness="10" type="hinge"/>
                  <geom fromto="0.4799 -0.0149 0.4121 0.6174 -0.0149 0.4121" size="0.0300" type="capsule"/>
                  <body name="lwrist" user="0.7261 -0.0149 0.4121">
                    <joint armature="0.01" axis="-1.0000 -0.0000 0.0000" damping="5" limited="true" name="lwrist_y" pos="0.6374 -0.0149 0.4121" range="-180.0000 0.0000" stiffness="10" type="hinge"/>
                    <geom fromto="0.6574 -0.0149 0.4121 0.7061 -0.0149 0.4121" size="0.0300" type="capsule"/>
                    <body name="lhand" user="0.7596 -0.0149 0.4121">
                      <joint armature="0.01" axis="0.0000 -0.0000 1.0000" damping="5" limited="true" name="lhand_z" pos="0.7261 -0.0149 0.4121" range="-45.0000 45.0000" stiffness="10" type="hinge"/>
                      <joint armature="0.01" axis="0.0000 1.0000 0.0000" damping="5" limited="true" name="lhand_x" pos="0.7261 -0.0149 0.4121" range="-90.0000 90.0000" stiffness="10" type="hinge"/>
                      <geom fromto="0.7461 -0.0149 0.4121 0.7396 -0.0149 0.4121" size="0.0300" type="capsule"/>
                      <body name="lfingers" user="0.7866 -0.0149 0.4121">
                        <joint armature="0.01" axis="0.0000 1.0000 0.0000" damping="5" limited="true" name="lfingers_x" pos="0.7596 -0.0149 0.4121" range="0.0000 90.0000" stiffness="10" type="hinge"/>
                        <geom fromto="0.7796 -0.0149 0.4121 0.7666 -0.0149 0.4121" size="0.0300" type="capsule"/>
                      </body>
                    </body>
                    <body name="lthumb" user="0.7535 -0.0423 0.4121">
                      <joint armature="0.01" axis="-0.0000 -0.0000 1.0000" damping="5" limited="true" name="lthumb_z" pos="0.7261 -0.0149 0.4121" range="-45.0000 45.0000" stiffness="10" type="hinge"/>
                      <joint armature="0.01" axis="0.7071 0.7071 0.0000" damping="5" limited="true" name="lthumb_x" pos="0.7261 -0.0149 0.4121" range="-45.0000 45.0000" stiffness="10" type="hinge"/>
                      <geom fromto="0.7403 -0.0290 0.4121 0.7394 -0.0282 0.4121" size="0.0300" type="capsule"/>
                    </body>
                  </body>
                </body>
              </body>
            </body>
            <body name="rclavicle" user="-0.1790 -0.0149 0.4121">
              <joint armature="0.01" axis="0.0000 -1.0000 0.0000" damping="5" limited="true" name="rclavicle_z" pos="-0.0010 0.0024 0.3407" range="-20.0000 0.0000" stiffness="10" type="hinge"/>
              <joint armature="0.01" axis="0.0000 -0.0000 1.0000" damping="5" limited="true" name="rclavicle_y" pos="-0.0010 0.0024 0.3407" range="-10.0000 20.0000" stiffness="10" type="hinge"/>
              <geom fromto="-0.0334 -0.0007 0.3537 -0.1466 -0.0118 0.3991" size="0.0300" type="capsule"/>
              <body name="rhumerus" user="-0.4599 -0.0149 0.4121">
                <joint armature="0.01" axis="0.0000 0.8660 -0.5000" damping="5" limited="true" name="rhumerus_z" pos="-0.1790 -0.0149 0.4121" range="-90.0000 90.0000" stiffness="10" type="hinge"/>
                <joint armature="0.01" axis="1.0000 -0.0000 -0.0000" damping="5" limited="true" name="rhumerus_y" pos="-0.1790 -0.0149 0.4121" range="-90.0000 90.0000" stiffness="10" type="hinge"/>
                <joint armature="0.01" axis="0.0000 0.5000 0.8660" damping="5" limited="true" name="rhumerus_x" pos="-0.1790 -0.0149 0.4121" range="-90.0000 60.0000" stiffness="10" type="hinge"/>
                <geom fromto="-0.2065 -0.0149 0.4121 -0.4324 -0.0149 0.4121" size="0.0300" type="capsule"/>
                <body name="rradius" user="-0.6374 -0.0149 0.4121">
                  <joint armature="0.01" axis="0.0000 0.5000 0.8660" damping="5" limited="true" name="rradius_x" pos="-0.4599 -0.0149 0.4121" range="-10.0000 170.0000" stiffness="10" type="hinge"/>
                  <geom fromto="-0.4799 -0.0149 0.4121 -0.6174 -0.0149 0.4121" size="0.0300" type="capsule"/>
                  <body name="rwrist" user="-0.7261 -0.0149 0.4121">
                    <joint armature="0.01" axis="1.0000 -0.0000 0.0000" damping="5" limited="true" name="rwrist_y" pos="-0.6374 -0.0149 0.4121" range="-180.0000 0.0000" stiffness="10" type="hinge"/>
                    <geom fromto="-0.6574 -0.0149 0.4121 -0.7061 -0.0149 0.4121" size="0.0300" type="capsule"/>
                    <body name="rhand" user="-0.7596 -0.0149 0.4121">
                      <joint armature="0.01" axis="-0.0000 -0.0000 1.0000" damping="5" limited="true" name="rhand_z" pos="-0.7261 -0.0149 0.4121" range="-45.0000 45.0000" stiffness="10" type="hinge"/>
                      <joint armature="0.01" axis="0.0000 -1.0000 -0.0000" damping="5" limited="true" name="rhand_x" pos="-0.7261 -0.0149 0.4121" range="-90.0000 90.0000" stiffness="10" type="hinge"/>
                      <geom fromto="-0.7461 -0.0149 0.4121 -0.7396 -0.0149 0.4121" size="0.0300" type="capsule"/>
                      <body name="rfingers" user="-0.7866 -0.0149 0.4121">
                        <joint armature="0.01" axis="0.0000 -1.0000 -0.0000" damping="5" limited="true" name="rfingers_x" pos="-0.7596 -0.0149 0.4121" range="0.0000 90.0000" stiffness="10" type="hinge"/>
                        <geom fromto="-0.7796 -0.0149 0.4121 -0.7666 -0.0149 0.4121" size="0.0300" type="capsule"/>
                      </body>
                    </body>
                    <body name="rthumb" user="-0.7535 -0.0423 0.4121">
                      <joint armature="0.01" axis="0.0000 -0.0000 1.0000" damping="5" limited="true" name="rthumb_z" pos="-0.7261 -0.0149 0.4121" range="-45.0000 45.0000" stiffness="10" type="hinge"/>
                      <joint armature="0.01" axis="0.7071 -0.7071 -0.0000" damping="5" limited="true" name="rthumb_x" pos="-0.7261 -0.0149 0.4121" range="-45.0000 45.0000" stiffness="10" type="hinge"/>
                      <geom fromto="-0.7403 -0.0290 0.4121 -0.7394 -0.0282 0.4121" size="0.0300" type="capsule"/>
                    </body>
                  </body>
                </body>
              </body>
            </body>
          </body>
        </body>
      </body>
    </body>
  </worldbody>
  <actuator>
    <motor gear="100" joint="lfemur_x" name="lfemur_x"/>
    <motor gear="100" joint="lfemur_y" name="lfemur_y"/>
    <motor gear="100" joint="lfemur_z" name="lfemur_z"/>
    <motor gear="100" joint="ltibia_x" name="ltibia_x"/>
    <motor gear="100" joint="lfoot_x" name="lfoot_x"/>
    <motor gear="100" joint="lfoot_z" name="lfoot_z"/>
    <motor gear="100" joint="ltoes_x" name="ltoes_x"/>
    <motor gear="100" joint="rfemur_x" name="rfemur_x"/>
    <motor gear="100" joint="rfemur_y" name="rfemur_y"/>
    <motor gear="100" joint="rfemur_z" name="rfemur_z"/>
    <motor gear="100" joint="rtibia_x" name="rtibia_x"/>
    <motor gear="100" joint="rfoot_x" name="rfoot_x"/>
    <motor gear="100" joint="rfoot_z" name="rfoot_z"/>
    <motor gear="100" joint="rtoes_x" name="rtoes_x"/>
    <motor gear="100" joint="lowerback_x" name="lowerback_x"/>
    <motor gear="100" joint="lowerback_y" name="lowerback_y"/>
    <motor gear="100" joint="lowerback_z" name="lowerback_z"/>
    <motor gear="100" joint="upperback_x" name="upperback_x"/>
    <motor gear="100" joint="upperback_y" name="upperback_y"/>
    <motor gear="100" joint="upperback_z" name="upperback_z"/>
    <motor gear="100" joint="thorax_x" name="thorax_x"/>
    <motor gear="100" joint="thorax_y" name="thorax_y"/>
    <motor gear="100" joint="thorax_z" name="thorax_z"/>
    <motor gear="100" joint="lowerneck_x" name="lowerneck_x"/>
    <motor gear="100" joint="lowerneck_y" name="lowerneck_y"/>
    <motor gear="100" joint="lowerneck_z" name="lowerneck_z"/>
    <motor gear="100" joint="upperneck_x" name="upperneck_x"/>
    <motor gear="100" joint="upperneck_y" name="upperneck_y"/>
    <motor gear="100" joint="upperneck_z" name="upperneck_z"/>
    <motor gear="100" joint="head_x" name="head_x"/>
    <motor gear="100" joint="head_y" name="head_y"/>
    <motor gear="100" joint="head_z" name="head_z"/>
    <motor gear="100" joint="lclavicle_y" name="lclavicle_y"/>
    <motor gear="100" joint="lclavicle_z" name="lclavicle_z"/>
    <motor gear="100" joint="lhumerus_x" name="lhumerus_x"/>
    <motor gear="100" joint="lhumerus_y" name="lhumerus_y"/>
    <motor gear="100" joint="lhumerus_z" name="lhumerus_z"/>
    <motor gear="100" joint="lradius_x" name="lradius_x"/>
    <motor gear="100" joint="lwrist_y" name="lwrist_y"/>
    <motor gear="100" joint="lhand_x" name="lhand_x"/>
    <motor gear="100" joint="lhand_z" name="lhand_z"/>
    <motor gear="100" joint="lfingers_x" name="lfingers_x"/>
    <motor gear="100" joint="lthumb_x" name="lthumb_x"/>
    <motor gear="100" joint="lthumb_z" name="lthumb_z"/>
    <motor gear="100" joint="rclavicle_y" name="rclavicle_y"/>
    <motor gear="100" joint="rclavicle_z" name="rclavicle_z"/>
    <motor gear="100" joint="rhumerus_x" name="rhumerus_x"/>
    <motor gear="100" joint="rhumerus_y" name="rhumerus_y"/>
    <motor gear="100" joint="rhumerus_z" name="rhumerus_z"/>
    <motor gear="100" joint="rradius_x" name="rradius_x"/>
    <motor gear="100" joint="rwrist_y" name="rwrist_y"/>
    <motor gear="100" joint="rhand_x" name="rhand_x"/>
    <motor gear="100" joint="rhand_z" name="rhand_z"/>
    <motor gear="100" joint="rfingers_x" name="rfingers_x"/>
    <motor gear="100" joint="rthumb_x" name="rthumb_x"/>
    <motor gear="100" joint="rthumb_z" name="rthumb_z"/>
  </actuator>
</mujoco>
